  <?xml version="1.0" ?>
  <!-- =================================================================================== -->
  <!-- |    This document was autogenerated by xacro from /homes/qli/catkin_ws/src/agni_robots/agni_description/robots/bimanual.urdf.xacro | -->
  <!-- |    EDITING THIS FILE BY HAND IS NOT RECOMMENDED                                 | -->
  <!-- =================================================================================== -->
  <robot name="bimanual" xmlns:xacro="http://www.ros.org/wiki/xacro">
    <link name="world"/>
    <material name="Silver">
      <color rgba="0.5 0.5 0.5 1.0"/>
    </material>
    <material name="DarkGrey">
      <color rgba="0.3 0.3 0.3 1.0"/>
    </material>
    <material name="Black">
      <color rgba="0 0 0 1.0"/>
    </material>
    <material name="Orange">
      <color rgba="1.0 0.487 0 1.0"/>
    </material>
    <link name="frame">
      <inertial>
        <mass value="100.0"/>
        <origin rpy="0 0 0" xyz="0 1.2 0.3"/>
        <inertia ixx="4.0" ixy="0" ixz="0" iyy="4.0" iyz="0" izz="4.0"/>
      </inertial>
      <visual>
        <origin rpy="0 -1.57079632679 0" xyz="0 0.045 -0.045"/>
        <geometry>
          <box size="0.09 0.09 1.92"/>
        </geometry>
        <material name="Silver"/>
      </visual>
      <collision>
        <origin rpy="0 -1.57079632679 0" xyz="0 0.045 -0.045"/>
        <geometry>
          <box size="0.09 0.09 1.92"/>
        </geometry>
      </collision>
      <visual>
        <origin rpy="0 -1.57079632679 0" xyz="0 1.865 -0.045"/>
        <geometry>
          <box size="0.09 0.09 1.92"/>
        </geometry>
        <material name="Silver"/>
      </visual>
      <collision>
        <origin rpy="0 -1.57079632679 0" xyz="0 1.865 -0.045"/>
        <geometry>
          <box size="0.09 0.09 1.92"/>
        </geometry>
      </collision>
      <visual>
        <origin rpy="0 -1.57079632679 0" xyz="0 1.865 1.305"/>
        <geometry>
          <box size="0.09 0.09 1.92"/>
        </geometry>
        <material name="Silver"/>
      </visual>
      <collision>
        <origin rpy="0 -1.57079632679 0" xyz="0 1.865 1.305"/>
        <geometry>
          <box size="0.09 0.09 1.92"/>
        </geometry>
      </collision>
      <visual>
        <origin xyz="-1.005 0.045 -0.545"/>
        <geometry>
          <box size="0.09 0.09 1.09"/>
        </geometry>
        <material name="Silver"/>
      </visual>
      <collision>
        <origin xyz="-1.005 0.045 -0.545"/>
        <geometry>
          <box size="0.09 0.09 1.09"/>
        </geometry>
      </collision>
      <visual>
        <origin xyz="1.005 0.045 -0.545"/>
        <geometry>
          <box size="0.09 0.09 1.09"/>
        </geometry>
        <material name="Silver"/>
      </visual>
      <collision>
        <origin xyz="1.005 0.045 -0.545"/>
        <geometry>
          <box size="0.09 0.09 1.09"/>
        </geometry>
      </collision>
      <visual>
        <origin xyz="-1.005 1.865 0.13"/>
        <geometry>
          <box size="0.09 0.09 2.44"/>
        </geometry>
        <material name="Silver"/>
      </visual>
      <collision>
        <origin xyz="-1.005 1.865 0.13"/>
        <geometry>
          <box size="0.09 0.09 2.44"/>
        </geometry>
      </collision>
      <visual>
        <origin xyz="1.005 1.865 0.13"/>
        <geometry>
          <box size="0.09 0.09 2.44"/>
        </geometry>
        <material name="Silver"/>
      </visual>
      <collision>
        <origin xyz="1.005 1.865 0.13"/>
        <geometry>
          <box size="0.09 0.09 2.44"/>
        </geometry>
      </collision>
      <visual>
        <origin rpy="-1.57079632679 0 0" xyz="-1.005 0.91 -0.045"/>
        <geometry>
          <box size="0.09 0.09 1.82"/>
        </geometry>
        <material name="Silver"/>
      </visual>
      <collision>
        <origin rpy="-1.57079632679 0 0" xyz="-1.005 0.91 -0.045"/>
        <geometry>
          <box size="0.09 0.09 1.82"/>
        </geometry>
      </collision>
      <visual>
        <origin rpy="-1.57079632679 0 0" xyz="1.005 0.91 -0.045"/>
        <geometry>
          <box size="0.09 0.09 1.82"/>
        </geometry>
        <material name="Silver"/>
      </visual>
      <collision>
        <origin rpy="-1.57079632679 0 0" xyz="1.005 0.91 -0.045"/>
        <geometry>
          <box size="0.09 0.09 1.82"/>
        </geometry>
      </collision>
      <visual>
        <origin xyz="-0.09 1.09 -0.23"/>
        <geometry>
          <box size="0.09 0.09 1.72"/>
        </geometry>
        <material name="Silver"/>
      </visual>
      <collision>
        <origin xyz="-0.09 1.09 -0.23"/>
        <geometry>
          <box size="0.09 0.09 1.72"/>
        </geometry>
      </collision>
      <visual>
        <origin xyz="0.09 1.09 -0.23"/>
        <geometry>
          <box size="0.09 0.09 1.72"/>
        </geometry>
        <material name="Silver"/>
      </visual>
      <collision>
        <origin xyz="0.09 1.09 -0.23"/>
        <geometry>
          <box size="0.09 0.09 1.72"/>
        </geometry>
      </collision>
      <!-- virtual protection plane for the screens -->
      <!-- right screen -->
      <visual>
        <origin rpy="0 0 0" xyz="-0.66 1.73 1.26"/>
        <geometry>
          <box size="0.6 0.1 0.4"/>
        </geometry>
        <material name="Silver"/>
      </visual>
      <!-- left screen -->
      <visual>
        <origin rpy="0 0 0" xyz="0.66 1.73 1.26"/>
        <geometry>
          <box size="0.6 0.1 0.4"/>
        </geometry>
        <material name="Silver"/>
      </visual>
      <collision>
        <origin rpy="0 0 0" xyz="0 1.64 0.63"/>
        <geometry>
          <box size="2.1 0.01 1.84"/>
        </geometry>
      </collision>
      <!-- kuka mount triangle -->
      <!-- left plate -->
      <visual>
        <origin rpy="0 1.0471975512 0" xyz="0.0784397459622                  0.89885                  0.29145"/>
        <geometry>
          <box size="0.26 0.26 0.02"/>
        </geometry>
        <material name="Silver"/>
      </visual>
      <collision>
        <origin rpy="0 1.0471975512 0" xyz="0.0784397459622                  0.89885                  0.29145"/>
        <geometry>
          <box size="0.26 0.26 0.015"/>
        </geometry>
      </collision>
      <!-- right plate -->
      <visual>
        <origin rpy="0 -1.0471975512 0" xyz="-0.0716397459622                  0.89885                  0.29145"/>
        <geometry>
          <box size="0.26 0.26 0.02"/>
        </geometry>
        <material name="Silver"/>
      </visual>
      <collision>
        <origin rpy="0 -1.0471975512 0" xyz="-0.0716397459622                  0.89885                  0.29145"/>
        <geometry>
          <box size="0.26 0.26 0.015"/>
        </geometry>
      </collision>
      <!-- lower plate -->
      <visual>
        <origin rpy="0 0 0" xyz="0 0.89885 0.163866697508"/>
        <geometry>
          <box size="0.26 0.26 0.02"/>
        </geometry>
        <material name="Silver"/>
      </visual>
      <collision>
        <origin rpy="0 0 0" xyz="0 0.89885 0.163866697508"/>
        <geometry>
          <box size="0.26 0.26 0.015"/>
        </geometry>
      </collision>
      <!-- table plane -->
      <visual>
        <origin rpy="0 0 0" xyz="0 0.91 -0.01"/>
        <geometry>
          <box size="1.92 1.82 0.02"/>
        </geometry>
        <material name="Silver"/>
      </visual>
      <collision>
        <origin rpy="0 0 0" xyz="0 0.91 -0.01"/>
        <geometry>
          <box size="1.92 1.82 0.02"/>
        </geometry>
      </collision>
    </link>
    <gazebo reference="frame">
      <material value="Gazebo/Grey"/>
    </gazebo>
    <joint name="frame_joint" type="fixed">
      <origin rpy="0 0 0" xyz="0 0 0"/>
      <parent link="world"/>
      <child link="frame"/>
    </joint>
    <!-- KUKA arm -->
    <link name="la_arm_base_link">
      <inertial>
        <mass value="1.2"/>
        <origin rpy="0 0 0" xyz="0 0 0.055"/>
        <inertia ixx="0.00229" ixy="0" ixz="0" iyy="0.00216" iyz="0" izz="0.00229"/>
      </inertial>
      <visual>
        <origin rpy="0 0 0" xyz="0 0 0"/>
        <geometry>
          <mesh filename="package://lwr_description/meshes/arm_base.dae" scale="100 100 100"/>
        </geometry>
        <material name="Orange"/>
      </visual>
      <collision>
        <origin rpy="0 0 0" xyz="0 0 0.01"/>
        <geometry>
          <mesh filename="package://lwr_description/meshes/convex/arm_base_convex.stl" scale="0.9 0.9 0.9"/>
        </geometry>
      </collision>
    </link>
    <gazebo reference="la_arm_base_link">
      <!--<material value="kuka-lwr.material"/>-->
    </gazebo>
    <joint name="la_arm_0_joint" type="revolute">
      <origin rpy="0 0 0" xyz="0 0 0.11"/>
      <axis xyz="0 0 1"/>
      <limit effort="204" lower="-2.96705972839" upper="2.96705972839" velocity="1.91986217719"/>
      <safety_controller k_position="100" k_velocity="2" soft_lower_limit="-2.93215314335" soft_upper_limit="2.93215314335"/>
      <dynamics damping="5.0"/>
      <parent link="la_arm_base_link"/>
      <child link="la_arm_1_link"/>
    </joint>
    <gazebo reference="la_arm_0_joint">
      <provideFeedback>1</provideFeedback>
      <implicitSpringDamper>1</implicitSpringDamper>
    </gazebo>
    <transmission name="la_arm_0_trans" type="SimpleTransmission">
      <actuator name="la_arm_0_motor"/>
      <joint name="la_arm_0_joint"/>
      <mechanicalReduction>1.0</mechanicalReduction>
    </transmission>
    <link name="la_arm_1_link">
      <inertial>
        <mass value="2.0"/>
        <origin rpy="0 0 0" xyz="0 0 0.130"/>
        <inertia ixx="0.0136666666667" ixy="0" ixz="0" iyy="0.0118666666667" iyz="0" izz="0.003"/>
      </inertial>
      <visual>
        <origin rpy="0 0 3.14159265359" xyz="0 0 0"/>
        <geometry>
          <mesh filename="package://lwr_description/meshes/arm_segment_a.dae" scale="100 100 100"/>
        </geometry>
        <material name="Orange"/>
      </visual>
      <collision>
        <origin rpy="0 0 3.14159265359" xyz="0 0 0"/>
        <geometry>
          <mesh filename="package://lwr_description/meshes/convex/arm_segment_a_convex.stl" scale="1.0 1.0 1.0"/>
        </geometry>
      </collision>
    </link>
    <gazebo reference="la_arm_1_link">
      <!--<material value="kuka-lwr.material"/>-->
    </gazebo>
    <joint name="la_arm_1_joint" type="revolute">
      <origin rpy="0 0 0" xyz="0 0 0.20"/>
      <axis xyz="0 -1 0"/>
      <limit effort="306" lower="-2.09439510239" upper="2.09439510239" velocity="1.91986217719"/>
      <safety_controller k_position="100" k_velocity="2" soft_lower_limit="-2.05948851735" soft_upper_limit="2.05948851735"/>
      <dynamics damping="5.0"/>
      <parent link="la_arm_1_link"/>
      <child link="la_arm_2_link"/>
    </joint>
    <gazebo reference="la_arm_1_joint">
      <provideFeedback>1</provideFeedback>
      <implicitSpringDamper>1</implicitSpringDamper>
    </gazebo>
    <transmission name="la_arm_1_trans" type="pr2_mechanism_model/SimpleTransmission">
      <actuator name="la_arm_1_motor"/>
      <joint name="la_arm_1_joint"/>
      <mechanicalReduction>1.0</mechanicalReduction>
    </transmission>
    <link name="la_arm_2_link">
      <inertial>
        <mass value="2.0"/>
        <origin rpy="0 0 0" xyz="0 -0.06 0.07"/>
        <inertia ixx="0.0136666666667" ixy="0" ixz="0" iyy="0.0118666666667" iyz="0" izz="0.003"/>
      </inertial>
      <visual>
        <origin rpy="3.14159265359 0 3.14159265359" xyz="0 0 0.2"/>
        <geometry>
          <mesh filename="package://lwr_description/meshes/arm_segment_b.dae" scale="100 100 100"/>
        </geometry>
        <material name="Orange"/>
      </visual>
      <collision>
        <origin rpy="3.14159265359 0 3.14159265359" xyz="0 0 0.2"/>
        <geometry>
          <mesh filename="package://lwr_description/meshes/convex/arm_segment_b_convex.stl" scale="1.0 1.0 1.0"/>
        </geometry>
      </collision>
    </link>
    <gazebo reference="la_arm_2_link">
      <!--<material value="kuka-lwr.material"/>-->
    </gazebo>
    <joint name="la_arm_2_joint" type="revolute">
      <origin rpy="0 0 0" xyz="0 0 0.20"/>
      <axis xyz="0 0 1"/>
      <limit effort="204" lower="-2.96705972839" upper="2.96705972839" velocity="2.26892802759"/>
      <safety_controller k_position="100" k_velocity="2" soft_lower_limit="-2.93215314335" soft_upper_limit="2.93215314335"/>
      <dynamics damping="3.0"/>
      <parent link="la_arm_2_link"/>
      <child link="la_arm_3_link"/>
    </joint>
    <gazebo reference="la_arm_2_joint">
      <provideFeedback>1</provideFeedback>
      <implicitSpringDamper>1</implicitSpringDamper>
    </gazebo>
    <transmission name="la_arm_2_trans" type="SimpleTransmission">
      <actuator name="la_arm_2_motor"/>
      <joint name="la_arm_2_joint"/>
      <mechanicalReduction>1.0</mechanicalReduction>
    </transmission>
    <link name="la_arm_3_link">
      <inertial>
        <mass value="2.0"/>
        <origin rpy="0 0 0" xyz="0 -0.06 0.130"/>
        <inertia ixx="0.0136666666667" ixy="0" ixz="0" iyy="0.0118666666667" iyz="0" izz="0.003"/>
      </inertial>
      <visual>
        <origin rpy="0 0 0" xyz="0 0 0"/>
        <geometry>
          <mesh filename="package://lwr_description/meshes/arm_segment_a.dae" scale="100 100 100"/>
        </geometry>
        <material name="Orange"/>
      </visual>
      <collision>
        <origin rpy="0 0 0" xyz="0 0 0"/>
        <geometry>
          <mesh filename="package://lwr_description/meshes/convex/arm_segment_a_convex.stl" scale="1.0 1.0 1.0"/>
        </geometry>
      </collision>
    </link>
    <gazebo reference="la_arm_3_link">
      <!--<material value="kuka-lwr.material"/>-->
    </gazebo>
    <joint name="la_arm_3_joint" type="revolute">
      <origin rpy="0 0 0" xyz="0 0 0.20"/>
      <axis xyz="0 1 0"/>
      <limit effort="306" lower="-2.09439510239" upper="2.09439510239" velocity="2.26892802759"/>
      <safety_controller k_position="100" k_velocity="2" soft_lower_limit="-2.05948851735" soft_upper_limit="2.05948851735"/>
      <dynamics damping="3.0"/>
      <parent link="la_arm_3_link"/>
      <child link="la_arm_4_link"/>
    </joint>
    <gazebo reference="la_arm_3_joint">
      <provideFeedback>1</provideFeedback>
      <implicitSpringDamper>1</implicitSpringDamper>
    </gazebo>
    <transmission name="la_arm_3_trans" type="SimpleTransmission">
      <actuator name="la_arm_3_motor"/>
      <joint name="la_arm_3_joint"/>
      <mechanicalReduction>1.0</mechanicalReduction>
    </transmission>
    <link name="la_arm_4_link">
      <inertial>
        <mass value="2.0"/>
        <origin rpy="0 0 0" xyz="0 0.06 0.07"/>
        <inertia ixx="0.0136666666667" ixy="0" ixz="0" iyy="0.0118666666667" iyz="0" izz="0.003"/>
      </inertial>
      <visual>
        <origin rpy="0 3.14159265359 3.14159265359" xyz="0 0 0.2"/>
        <geometry>
          <mesh filename="package://lwr_description/meshes/arm_segment_b.dae" scale="100 100 100"/>
        </geometry>
        <material name="Orange"/>
      </visual>
      <collision>
        <origin rpy="0 3.14159265359 3.14159265359" xyz="0 0 0.2"/>
        <geometry>
          <mesh filename="package://lwr_description/meshes/convex/arm_segment_b_convex.stl" scale="1.0 1.0 1.0"/>
        </geometry>
      </collision>
    </link>
    <gazebo reference="la_arm_4_link">
      <!--<material value="kuka-lwr.material"/>-->
    </gazebo>
    <joint name="la_arm_4_joint" type="revolute">
      <origin rpy="0 0 0" xyz="0 0 0.20"/>
      <axis xyz="0 0 1"/>
      <limit effort="204" lower="-2.96705972839" upper="2.96705972839" velocity="2.26892802759"/>
      <safety_controller k_position="100" k_velocity="2" soft_lower_limit="-2.93215314335" soft_upper_limit="2.93215314335"/>
      <dynamics damping="1.0"/>
      <parent link="la_arm_4_link"/>
      <child link="la_arm_5_link"/>
    </joint>
    <gazebo reference="la_arm_4_joint">
      <provideFeedback>1</provideFeedback>
      <implicitSpringDamper>1</implicitSpringDamper>
    </gazebo>
    <transmission name="la_arm_4_trans" type="SimpleTransmission">
      <actuator name="la_arm_4_motor"/>
      <joint name="la_arm_4_joint"/>
      <mechanicalReduction>1.0</mechanicalReduction>
    </transmission>
    <link name="la_arm_5_link">
      <inertial>
        <mass value="2.0"/>
        <origin rpy="0 0 0" xyz="0 0 0.124"/>
        <inertia ixx="0.0126506666667" ixy="0" ixz="0" iyy="0.0108506666667" iyz="0" izz="0.003"/>
      </inertial>
      <visual>
        <origin rpy="0 0 3.14159265359" xyz="0 0 0"/>
        <geometry name="la_arm_5_geom">
          <mesh filename="package://lwr_description/meshes/arm_segment_last.dae" scale="100 100 100"/>
        </geometry>
        <material name="Orange"/>
      </visual>
      <collision>
        <origin rpy="0 0 3.14159265359" xyz="0 0 0"/>
        <geometry>
          <mesh filename="package://lwr_description/meshes/convex/arm_segment_last_convex.stl" scale="1.0 1.0 1.0"/>
        </geometry>
      </collision>
    </link>
    <gazebo reference="la_arm_5_link">
      <!--<material value="kuka-lwr.material"/>-->
    </gazebo>
    <joint name="la_arm_5_joint" type="revolute">
      <origin rpy="0 0 0" xyz="0 0 0.19"/>
      <axis xyz="0 -1 0"/>
      <limit effort="306" lower="-2.09439510239" upper="2.09439510239" velocity="3.14159265359"/>
      <safety_controller k_position="100" k_velocity="2" soft_lower_limit="-2.05948851735" soft_upper_limit="2.05948851735"/>
      <dynamics damping="1.0"/>
      <parent link="la_arm_5_link"/>
      <child link="la_arm_6_link"/>
    </joint>
    <gazebo reference="la_arm_5_joint">
      <provideFeedback>1</provideFeedback>
      <implicitSpringDamper>1</implicitSpringDamper>
    </gazebo>
    <transmission name="la_arm_5_trans" type="SimpleTransmission">
      <actuator name="la_arm_5_motor"/>
      <joint name="la_arm_5_joint"/>
      <mechanicalReduction>1.0</mechanicalReduction>
    </transmission>
    <link name="la_arm_6_link">
      <inertial>
        <mass value="1.0"/>
        <origin rpy="0 0 0" xyz="0 0 0.0"/>
        <inertia ixx="0.00260416666667" ixy="0" ixz="0" iyy="0.00260416666667" iyz="0" izz="0.00260416666667"/>
      </inertial>
      <visual>
        <origin rpy="0 0 3.14159265359" xyz="0 0 0"/>
        <geometry>
          <mesh filename="package://lwr_description/meshes/arm_wrist.dae" scale="100 100 100"/>
        </geometry>
        <material name="Grey"/>
      </visual>
      <collision>
        <origin rpy="0 0 3.14159265359" xyz="0 0 0"/>
        <geometry>
          <mesh filename="package://lwr_description/meshes/convex/arm_wrist_convex.stl" scale="1.0 1.0 1.0"/>
        </geometry>
      </collision>
    </link>
    <gazebo reference="la_arm_6_link">
      <!--<material value="kuka-lwr.material"/>-->
    </gazebo>
    <joint name="la_arm_6_joint" type="revolute">
      <origin rpy="0 0 0" xyz="0 0 0.078"/>
      <axis xyz="0 0 1"/>
      <limit effort="204" lower="-2.96705972839" upper="2.96705972839" velocity="3.14159265359"/>
      <safety_controller k_position="100" k_velocity="2" soft_lower_limit="-2.93215314335" soft_upper_limit="2.93215314335"/>
      <dynamics damping="1.0"/>
      <parent link="la_arm_6_link"/>
      <child link="la_arm_7_link"/>
    </joint>
    <gazebo reference="la_arm_6_joint">
      <provideFeedback>1</provideFeedback>
      <implicitSpringDamper>1</implicitSpringDamper>
    </gazebo>
    <transmission name="la_arm_6_trans" type="SimpleTransmission">
      <actuator name="la_arm_6_motor"/>
      <joint name="la_arm_6_joint"/>
      <mechanicalReduction>1.0</mechanicalReduction>
    </transmission>
    <link name="la_arm_7_link">
      <inertial>
        <mass value="0.2"/>
        <origin xyz="0 0 0"/>
        <inertia ixx="6.66666666667e-05" ixy="0" ixz="0" iyy="6.66666666667e-05" iyz="0" izz="0.00012"/>
      </inertial>
      <visual>
        <origin rpy="0 0 0" xyz="0 0 0"/>
        <geometry>
          <mesh filename="package://lwr_description/meshes/arm_flanche.dae" scale="100 100 100"/>
        </geometry>
        <material name="Grey"/>
      </visual>
      <collision>
        <origin rpy="0 0 0" xyz="0 0 0"/>
        <geometry>
          <mesh filename="package://lwr_description/meshes/convex/arm_flanche_convex.stl" scale="1.0 1.0 1.0"/>
        </geometry>
      </collision>
    </link>
    <gazebo reference="la_arm_7_link">
      <!--<material value="kuka-lwr.material"/>-->
    </gazebo>
    <joint name="la_arm_hand_fixed_joint" type="fixed">
      <parent link="la_arm_7_link"/>
      <child link="la_tool_mount"/>
    </joint>
    <link name="la_tool_mount"/>
    <!-- add gazebo controllers -->
    <gazebo>
      <plugin filename="liblwr_controller.so" name="la_lwr_arm_controller">
        <alwaysOn>true</alwaysOn>
        <robotPrefix>la</robotPrefix>
        <robotNamespace>la</robotNamespace>
        <remotePort>49940</remotePort>
        <baseLink>la_arm_base_link</baseLink>
        <gravityDirection>7.3775 -4.2769 -4.8494</gravityDirection>
        <payloadMass>0.492</payloadMass>
        <payloadCOG>0.0 0.0 0.015</payloadCOG>
        <auto_on>1</auto_on>
        <la_arm_0_joint>-0.52</la_arm_0_joint>
        <la_arm_1_joint>1.04</la_arm_1_joint>
        <la_arm_2_joint>0</la_arm_2_joint>
        <la_arm_3_joint>0</la_arm_3_joint>
        <la_arm_4_joint>0</la_arm_4_joint>
        <la_arm_5_joint>0</la_arm_5_joint>
        <la_arm_6_joint>0</la_arm_6_joint>
      </plugin>
    </gazebo>
    <joint name="la_arm_mount" type="fixed">
      <parent link="world"/>
      <child link="la_arm_base_link"/>
      <origin rpy="0.7227 0.8512 0.849" xyz="0.0871 0.9011 0.2981"/>
    </joint>
    <!-- poking stick -->
    <link name="lh_poking_stick">
      <inertial>
        <mass value="0.492"/>
        <!-- to get a total mass of the real assembly with distal of 505g -->
        <origin xyz="0 0 0.092"/>
        <inertia ixx="0.000651" ixy="0.0" ixz="0.0" iyy="0.000651" iyz="0.0" izz="0.000896"/>
      </inertial>
      <visual>
        <origin rpy="0 0 0" xyz="0 0 0"/>
        <geometry>
          <mesh filename="package://agni_description/models/meshes/poking_stick.dae" scale="0.001 0.001 0.001"/>
        </geometry>
      </visual>
      <collision>
        <origin rpy="0 0 0" xyz="0 0 0.0075"/>
        <geometry>
          <cylinder length="0.015" radius="0.06725"/>
        </geometry>
      </collision>
      <collision>
        <origin rpy="0 0 0" xyz="0 0 0.08875"/>
        <geometry>
          <cylinder length="0.1475" radius="0.0075"/>
        </geometry>
      </collision>
      <collision>
        <origin rpy="0 0 0" xyz="0 0 0.1625"/>
        <geometry>
          <sphere radius="0.0075"/>
        </geometry>
      </collision>
    </link>
    <gazebo reference="lh_poking_stick">
    </gazebo>
    <joint name="lh_tool_mount" type="fixed">
      <parent link="la_tool_mount"/>
      <child link="lh_poking_stick"/>
      <origin rpy="0.0 0.0 0.0" xyz="0.0 0.0 0.0"/>
    </joint>
    <!-- KUKA arm -->
    <link name="ra_arm_base_link">
      <inertial>
        <mass value="1.2"/>
        <origin rpy="0 0 0" xyz="0 0 0.055"/>
        <inertia ixx="0.00229" ixy="0" ixz="0" iyy="0.00216" iyz="0" izz="0.00229"/>
      </inertial>
      <visual>
        <origin rpy="0 0 0" xyz="0 0 0"/>
        <geometry>
          <mesh filename="package://lwr_description/meshes/arm_base.dae" scale="100 100 100"/>
        </geometry>
        <material name="Orange"/>
      </visual>
      <collision>
        <origin rpy="0 0 0" xyz="0 0 0.01"/>
        <geometry>
          <mesh filename="package://lwr_description/meshes/convex/arm_base_convex.stl" scale="0.9 0.9 0.9"/>
        </geometry>
      </collision>
    </link>
    <gazebo reference="ra_arm_base_link">
      <!--<material value="kuka-lwr.material"/>-->
    </gazebo>
    <joint name="ra_arm_0_joint" type="revolute">
      <origin rpy="0 0 0" xyz="0 0 0.11"/>
      <axis xyz="0 0 1"/>
      <limit effort="204" lower="-2.96705972839" upper="2.96705972839" velocity="1.91986217719"/>
      <safety_controller k_position="100" k_velocity="2" soft_lower_limit="-2.93215314335" soft_upper_limit="2.93215314335"/>
      <dynamics damping="5.0"/>
      <parent link="ra_arm_base_link"/>
      <child link="ra_arm_1_link"/>
    </joint>
    <gazebo reference="ra_arm_0_joint">
      <provideFeedback>1</provideFeedback>
      <implicitSpringDamper>1</implicitSpringDamper>
    </gazebo>
    <transmission name="ra_arm_0_trans" type="SimpleTransmission">
      <actuator name="ra_arm_0_motor"/>
      <joint name="ra_arm_0_joint"/>
      <mechanicalReduction>1.0</mechanicalReduction>
    </transmission>
    <link name="ra_arm_1_link">
      <inertial>
        <mass value="2.0"/>
        <origin rpy="0 0 0" xyz="0 0 0.130"/>
        <inertia ixx="0.0136666666667" ixy="0" ixz="0" iyy="0.0118666666667" iyz="0" izz="0.003"/>
      </inertial>
      <visual>
        <origin rpy="0 0 3.14159265359" xyz="0 0 0"/>
        <geometry>
          <mesh filename="package://lwr_description/meshes/arm_segment_a.dae" scale="100 100 100"/>
        </geometry>
        <material name="Orange"/>
      </visual>
      <collision>
        <origin rpy="0 0 3.14159265359" xyz="0 0 0"/>
        <geometry>
          <mesh filename="package://lwr_description/meshes/convex/arm_segment_a_convex.stl" scale="1.0 1.0 1.0"/>
        </geometry>
      </collision>
    </link>
    <gazebo reference="ra_arm_1_link">
      <!--<material value="kuka-lwr.material"/>-->
    </gazebo>
    <joint name="ra_arm_1_joint" type="revolute">
      <origin rpy="0 0 0" xyz="0 0 0.20"/>
      <axis xyz="0 -1 0"/>
      <limit effort="306" lower="-2.09439510239" upper="2.09439510239" velocity="1.91986217719"/>
      <safety_controller k_position="100" k_velocity="2" soft_lower_limit="-2.05948851735" soft_upper_limit="2.05948851735"/>
      <dynamics damping="5.0"/>
      <parent link="ra_arm_1_link"/>
      <child link="ra_arm_2_link"/>
    </joint>
    <gazebo reference="ra_arm_1_joint">
      <provideFeedback>1</provideFeedback>
      <implicitSpringDamper>1</implicitSpringDamper>
    </gazebo>
    <transmission name="ra_arm_1_trans" type="pr2_mechanism_model/SimpleTransmission">
      <actuator name="ra_arm_1_motor"/>
      <joint name="ra_arm_1_joint"/>
      <mechanicalReduction>1.0</mechanicalReduction>
    </transmission>
    <link name="ra_arm_2_link">
      <inertial>
        <mass value="2.0"/>
        <origin rpy="0 0 0" xyz="0 -0.06 0.07"/>
        <inertia ixx="0.0136666666667" ixy="0" ixz="0" iyy="0.0118666666667" iyz="0" izz="0.003"/>
      </inertial>
      <visual>
        <origin rpy="3.14159265359 0 3.14159265359" xyz="0 0 0.2"/>
        <geometry>
          <mesh filename="package://lwr_description/meshes/arm_segment_b.dae" scale="100 100 100"/>
        </geometry>
        <material name="Orange"/>
      </visual>
      <collision>
        <origin rpy="3.14159265359 0 3.14159265359" xyz="0 0 0.2"/>
        <geometry>
          <mesh filename="package://lwr_description/meshes/convex/arm_segment_b_convex.stl" scale="1.0 1.0 1.0"/>
        </geometry>
      </collision>
    </link>
    <gazebo reference="ra_arm_2_link">
      <!--<material value="kuka-lwr.material"/>-->
    </gazebo>
    <joint name="ra_arm_2_joint" type="revolute">
      <origin rpy="0 0 0" xyz="0 0 0.20"/>
      <axis xyz="0 0 1"/>
      <limit effort="204" lower="-2.96705972839" upper="2.96705972839" velocity="2.26892802759"/>
      <safety_controller k_position="100" k_velocity="2" soft_lower_limit="-2.93215314335" soft_upper_limit="2.93215314335"/>
      <dynamics damping="3.0"/>
      <parent link="ra_arm_2_link"/>
      <child link="ra_arm_3_link"/>
    </joint>
    <gazebo reference="ra_arm_2_joint">
      <provideFeedback>1</provideFeedback>
      <implicitSpringDamper>1</implicitSpringDamper>
    </gazebo>
    <transmission name="ra_arm_2_trans" type="SimpleTransmission">
      <actuator name="ra_arm_2_motor"/>
      <joint name="ra_arm_2_joint"/>
      <mechanicalReduction>1.0</mechanicalReduction>
    </transmission>
    <link name="ra_arm_3_link">
      <inertial>
        <mass value="2.0"/>
        <origin rpy="0 0 0" xyz="0 -0.06 0.130"/>
        <inertia ixx="0.0136666666667" ixy="0" ixz="0" iyy="0.0118666666667" iyz="0" izz="0.003"/>
      </inertial>
      <visual>
        <origin rpy="0 0 0" xyz="0 0 0"/>
        <geometry>
          <mesh filename="package://lwr_description/meshes/arm_segment_a.dae" scale="100 100 100"/>
        </geometry>
        <material name="Orange"/>
      </visual>
      <collision>
        <origin rpy="0 0 0" xyz="0 0 0"/>
        <geometry>
          <mesh filename="package://lwr_description/meshes/convex/arm_segment_a_convex.stl" scale="1.0 1.0 1.0"/>
        </geometry>
      </collision>
    </link>
    <gazebo reference="ra_arm_3_link">
      <!--<material value="kuka-lwr.material"/>-->
    </gazebo>
    <joint name="ra_arm_3_joint" type="revolute">
      <origin rpy="0 0 0" xyz="0 0 0.20"/>
      <axis xyz="0 1 0"/>
      <limit effort="306" lower="-2.09439510239" upper="2.09439510239" velocity="2.26892802759"/>
      <safety_controller k_position="100" k_velocity="2" soft_lower_limit="-2.05948851735" soft_upper_limit="2.05948851735"/>
      <dynamics damping="3.0"/>
      <parent link="ra_arm_3_link"/>
      <child link="ra_arm_4_link"/>
    </joint>
    <gazebo reference="ra_arm_3_joint">
      <provideFeedback>1</provideFeedback>
      <implicitSpringDamper>1</implicitSpringDamper>
    </gazebo>
    <transmission name="ra_arm_3_trans" type="SimpleTransmission">
      <actuator name="ra_arm_3_motor"/>
      <joint name="ra_arm_3_joint"/>
      <mechanicalReduction>1.0</mechanicalReduction>
    </transmission>
    <link name="ra_arm_4_link">
      <inertial>
        <mass value="2.0"/>
        <origin rpy="0 0 0" xyz="0 0.06 0.07"/>
        <inertia ixx="0.0136666666667" ixy="0" ixz="0" iyy="0.0118666666667" iyz="0" izz="0.003"/>
      </inertial>
      <visual>
        <origin rpy="0 3.14159265359 3.14159265359" xyz="0 0 0.2"/>
        <geometry>
          <mesh filename="package://lwr_description/meshes/arm_segment_b.dae" scale="100 100 100"/>
        </geometry>
        <material name="Orange"/>
      </visual>
      <collision>
        <origin rpy="0 3.14159265359 3.14159265359" xyz="0 0 0.2"/>
        <geometry>
          <mesh filename="package://lwr_description/meshes/convex/arm_segment_b_convex.stl" scale="1.0 1.0 1.0"/>
        </geometry>
      </collision>
    </link>
    <gazebo reference="ra_arm_4_link">
      <!--<material value="kuka-lwr.material"/>-->
    </gazebo>
    <joint name="ra_arm_4_joint" type="revolute">
      <origin rpy="0 0 0" xyz="0 0 0.20"/>
      <axis xyz="0 0 1"/>
      <limit effort="204" lower="-2.96705972839" upper="2.96705972839" velocity="2.26892802759"/>
      <safety_controller k_position="100" k_velocity="2" soft_lower_limit="-2.93215314335" soft_upper_limit="2.93215314335"/>
      <dynamics damping="1.0"/>
      <parent link="ra_arm_4_link"/>
      <child link="ra_arm_5_link"/>
    </joint>
    <gazebo reference="ra_arm_4_joint">
      <provideFeedback>1</provideFeedback>
      <implicitSpringDamper>1</implicitSpringDamper>
    </gazebo>
    <transmission name="ra_arm_4_trans" type="SimpleTransmission">
      <actuator name="ra_arm_4_motor"/>
      <joint name="ra_arm_4_joint"/>
      <mechanicalReduction>1.0</mechanicalReduction>
    </transmission>
    <link name="ra_arm_5_link">
      <inertial>
        <mass value="2.0"/>
        <origin rpy="0 0 0" xyz="0 0 0.124"/>
        <inertia ixx="0.0126506666667" ixy="0" ixz="0" iyy="0.0108506666667" iyz="0" izz="0.003"/>
      </inertial>
      <visual>
        <origin rpy="0 0 3.14159265359" xyz="0 0 0"/>
        <geometry name="ra_arm_5_geom">
          <mesh filename="package://lwr_description/meshes/arm_segment_last.dae" scale="100 100 100"/>
        </geometry>
        <material name="Orange"/>
      </visual>
      <collision>
        <origin rpy="0 0 3.14159265359" xyz="0 0 0"/>
        <geometry>
          <mesh filename="package://lwr_description/meshes/convex/arm_segment_last_convex.stl" scale="1.0 1.0 1.0"/>
        </geometry>
      </collision>
    </link>
    <gazebo reference="ra_arm_5_link">
      <!--<material value="kuka-lwr.material"/>-->
    </gazebo>
    <joint name="ra_arm_5_joint" type="revolute">
      <origin rpy="0 0 0" xyz="0 0 0.19"/>
      <axis xyz="0 -1 0"/>
      <limit effort="306" lower="-2.09439510239" upper="2.09439510239" velocity="3.14159265359"/>
      <safety_controller k_position="100" k_velocity="2" soft_lower_limit="-2.05948851735" soft_upper_limit="2.05948851735"/>
      <dynamics damping="1.0"/>
      <parent link="ra_arm_5_link"/>
      <child link="ra_arm_6_link"/>
    </joint>
    <gazebo reference="ra_arm_5_joint">
      <provideFeedback>1</provideFeedback>
      <implicitSpringDamper>1</implicitSpringDamper>
    </gazebo>
    <transmission name="ra_arm_5_trans" type="SimpleTransmission">
      <actuator name="ra_arm_5_motor"/>
      <joint name="ra_arm_5_joint"/>
      <mechanicalReduction>1.0</mechanicalReduction>
    </transmission>
    <link name="ra_arm_6_link">
      <inertial>
        <mass value="1.0"/>
        <origin rpy="0 0 0" xyz="0 0 0.0"/>
        <inertia ixx="0.00260416666667" ixy="0" ixz="0" iyy="0.00260416666667" iyz="0" izz="0.00260416666667"/>
      </inertial>
      <visual>
        <origin rpy="0 0 3.14159265359" xyz="0 0 0"/>
        <geometry>
          <mesh filename="package://lwr_description/meshes/arm_wrist.dae" scale="100 100 100"/>
        </geometry>
        <material name="Grey"/>
      </visual>
      <collision>
        <origin rpy="0 0 3.14159265359" xyz="0 0 0"/>
        <geometry>
          <mesh filename="package://lwr_description/meshes/convex/arm_wrist_convex.stl" scale="1.0 1.0 1.0"/>
        </geometry>
      </collision>
    </link>
    <gazebo reference="ra_arm_6_link">
      <!--<material value="kuka-lwr.material"/>-->
    </gazebo>
    <joint name="ra_arm_6_joint" type="revolute">
      <origin rpy="0 0 0" xyz="0 0 0.078"/>
      <axis xyz="0 0 1"/>
      <limit effort="204" lower="-2.96705972839" upper="2.96705972839" velocity="3.14159265359"/>
      <safety_controller k_position="100" k_velocity="2" soft_lower_limit="-2.93215314335" soft_upper_limit="2.93215314335"/>
      <dynamics damping="1.0"/>
      <parent link="ra_arm_6_link"/>
      <child link="ra_arm_7_link"/>
    </joint>
    <gazebo reference="ra_arm_6_joint">
      <provideFeedback>1</provideFeedback>
      <implicitSpringDamper>1</implicitSpringDamper>
    </gazebo>
    <transmission name="ra_arm_6_trans" type="SimpleTransmission">
      <actuator name="ra_arm_6_motor"/>
      <joint name="ra_arm_6_joint"/>
      <mechanicalReduction>1.0</mechanicalReduction>
    </transmission>
    <link name="ra_arm_7_link">
      <inertial>
        <mass value="0.2"/>
        <origin xyz="0 0 0"/>
        <inertia ixx="6.66666666667e-05" ixy="0" ixz="0" iyy="6.66666666667e-05" iyz="0" izz="0.00012"/>
      </inertial>
      <visual>
        <origin rpy="0 0 0" xyz="0 0 0"/>
        <geometry>
          <mesh filename="package://lwr_description/meshes/arm_flanche.dae" scale="100 100 100"/>
        </geometry>
        <material name="Grey"/>
      </visual>
      <collision>
        <origin rpy="0 0 0" xyz="0 0 0"/>
        <geometry>
          <mesh filename="package://lwr_description/meshes/convex/arm_flanche_convex.stl" scale="1.0 1.0 1.0"/>
        </geometry>
      </collision>
    </link>
    <gazebo reference="ra_arm_7_link">
      <!--<material value="kuka-lwr.material"/>-->
    </gazebo>
    <joint name="ra_arm_hand_fixed_joint" type="fixed">
      <parent link="ra_arm_7_link"/>
      <child link="ra_tool_mount"/>
    </joint>
    <link name="ra_tool_mount"/>
    <!-- add gazebo controllers -->
    <gazebo>
      <plugin filename="liblwr_controller.so" name="ra_lwr_arm_controller">
        <alwaysOn>true</alwaysOn>
        <robotPrefix>ra</robotPrefix>
        <robotNamespace>ra</robotNamespace>
        <remotePort>49938</remotePort>
        <baseLink>ra_arm_base_link</baseLink>
        <gravityDirection>7.2512 4.2925 -5.023</gravityDirection>
        <payloadMass>0.185</payloadMass>
        <payloadCOG>0.0 0.0 0.01</payloadCOG>
        <auto_on>1</auto_on>
        <ra_arm_0_joint>0.52</ra_arm_0_joint>
        <ra_arm_1_joint>1.04</ra_arm_1_joint>
        <ra_arm_2_joint>0</ra_arm_2_joint>
        <ra_arm_3_joint>0</ra_arm_3_joint>
        <ra_arm_4_joint>0</ra_arm_4_joint>
        <ra_arm_5_joint>0</ra_arm_5_joint>
        <ra_arm_6_joint>0</ra_arm_6_joint>
      </plugin>
    </gazebo>
    <joint name="ra_arm_mount" type="fixed">
      <parent link="world"/>
      <child link="ra_arm_base_link"/>
      <origin rpy="-0.7071 0.8318 2.2734" xyz="-0.0803 0.8966 0.2948"/>
    </joint>
    <link name="rh_myrmex_quick_mount">
      <inertial>
        <origin rpy="0 0 0" xyz="0 0 0.03"/>
        <mass value="0.180"/>
        <inertia ixx="0.0002" ixy="0.0" ixz="0.0" iyy="0.0002" iyz="0.0" izz="0.0001"/>
      </inertial>
      <visual>
        <origin rpy="0 0 0" xyz="0 0 0"/>
        <geometry>
          <mesh filename="package://agni_description/models/meshes/myrmex_quick_mount.dae" scale="0.001 0.001 0.001"/>
        </geometry>
      </visual>
      <collision>
        <origin rpy="0 0 0" xyz="0 0 0.00797"/>
        <geometry>
          <cylinder length="0.01584" radius="0.06725"/>
        </geometry>
      </collision>
      <collision>
        <origin rpy="0 0 0" xyz="0 0 0.02159"/>
        <geometry>
          <cylinder length="0.0115" radius="0.060"/>
        </geometry>
      </collision>
    </link>
    <joint name="rh_myrmex_bumper_joint" type="prismatic">
      <parent link="rh_myrmex_quick_mount"/>
      <child link="rh_myrmex_foam"/>
      <origin rpy="0 0 0" xyz="0 0 0.03034"/>
      <axis xyz="0 0 1"/>
      <limit effort="1" lower="0.0" upper="0.001" velocity="0.1"/>
    </joint>
    <link name="rh_myrmex_foam">
      <inertial>
        <origin rpy="0 0 0" xyz="0 0 0.0"/>
        <mass value="0.005"/>
        <inertia ixx="0.000002" ixy="0.0" ixz="0.0" iyy="0.000002" iyz="0.0" izz="0.000001"/>
      </inertial>
      <visual>
        <origin rpy="0 0 0" xyz="0 0 0"/>
        <geometry>
          <box size="0.095 0.095 0.006"/>
        </geometry>
      </visual>
      <collision name="rh_myrmex_foam">
        <origin rpy="0 0 0" xyz="0 0 0"/>
        <geometry>
          <mesh filename="package://agni_description/models/meshes/myrmex_foam.stl" scale="1.0 1.0 1.0"/>
          <!--box size="0.095 0.095 0.006"/-->
        </geometry>
      </collision>
    </link>
    <gazebo reference="rh_myrmex_foam">
      <material>Gazebo/Black</material>
      <sensor name="rh_myrmex_sensor" type="contact">
        <always_on>1</always_on>
        <update_rate>1000.0</update_rate>
        <contact>
          <collision>rh_myrmex_foam_collision</collision>
          <topic>rh_myrmex_foam_collision</topic>
        </contact>
        <plugin filename="libgazebo_ros_tactile.so" name="rh_myrmex_gazebo_ros_tactile_controller">
          <alwaysOn>true</alwaysOn>
          <robotNamespace>rh</robotNamespace>
          <frameName>rh_myrmex_foam</frameName>
          <updateRate>100.0</updateRate>
          <bumperTopicName>contacts/rh_myrmex</bumperTopicName>
          <tactileTopicName>tactile_contact_states/rh_myrmex</tactileTopicName>
        </plugin>
      </sensor>
    </gazebo>
    <!-- tactile marker mapping description -->
    <sensor name="rh_myrmex_sensor" update_rate="100">
      <parent link="rh_myrmex_quick_mount"/>
      <origin rpy="0 0 0" xyz="0 0 0.034"/>
      <tactile channel="rh_myrmex">
        <array cols="16" offset="0.0375 0.0375" order="row-major" rows="16" size="0.005 0.005">
          </array>
      </tactile>
    </sensor>
    <joint name="rh_tool_mount" type="fixed">
      <parent link="ra_tool_mount"/>
      <child link="rh_myrmex_quick_mount"/>
      <origin rpy="0.0 0.0 0.0" xyz="0.0 0.0 0.0"/>
    </joint>
  </robot>